<?xml version="1.0" encoding="utf-8"?>
<!-- This URDF was automatically created by SolidWorks to URDF Exporter! Originally created by Stephen Brawner (brawner@gmail.com) 
     Commit Version: 1.6.0-4-g7f85cfe  Build Version: 1.6.7995.38578
     For more information, please see http://wiki.ros.org/sw_urdf_exporter -->
<robot
  name="srbot_description">
  <link
    name="base_link">
    <inertial>
      <origin
        xyz="0.20784 0.79758 0.40646"
        rpy="0 0 0" />
      <mass
        value="8.9517" />
      <inertia
        ixx="0.1856"
        ixy="0.0038526"
        ixz="7.8614E-07"
        iyy="0.16844"
        iyz="-7.4146E-07"
        izz="0.13754" />
    </inertial>
    <visual>
      <origin
        xyz="0 0 0"
        rpy="0 0 0" />
      <geometry>
        <mesh
          filename="package://srbot_description/meshes/base_link.STL" />
      </geometry>
      <material
        name="">
        <color
          rgba="0.79216 0.81961 0.93333 1" />
      </material>
    </visual>
    <collision>
      <origin
        xyz="0 0 0"
        rpy="0 0 0" />
      <geometry>
        <mesh
          filename="package://srbot_description/meshes/base_link.STL" />
      </geometry>
    </collision>
  </link>
  <link
    name="right_wheel">
    <inertial>
      <origin
        xyz="0 0 0.0175"
        rpy="0 0 0" />
      <mass
        value="0.19993" />
      <inertia
        ixx="0.0001654"
        ixy="-1.2262E-19"
        ixz="7.8909E-21"
        iyy="0.0001654"
        iyz="5.4847E-23"
        izz="0.00028999" />
    </inertial>
    <visual>
      <origin
        xyz="0 0 0"
        rpy="0 0 0" />
      <geometry>
        <mesh
          filename="package://srbot_description/meshes/right_wheel.STL" />
      </geometry>
      <material
        name="">
        <color
          rgba="0.79216 0.81961 0.93333 1" />
      </material>
    </visual>
    <collision>
      <origin
        xyz="0 0 0"
        rpy="0 0 0" />
      <geometry>
        <mesh
          filename="package://srbot_description/meshes/right_wheel.STL" />
      </geometry>
    </collision>
  </link>
  <joint
    name="right_joint"
    type="continuous">
    <origin
      xyz="0.1389 -0.57143 0.28518"
      rpy="1.5708 0 0" />
    <parent
      link="base_link" />
    <child
      link="right_wheel" />
    <axis
      xyz="0 0 0" />
  </joint>
  <link
    name="left_wheel">
    <inertial>
      <origin
        xyz="2.7756E-17 -0.0014195 -0.0175"
        rpy="0 0 0" />
      <mass
        value="0.19993" />
      <inertia
        ixx="0.0001654"
        ixy="-1.2289E-19"
        ixz="4.0509E-22"
        iyy="0.0001654"
        iyz="4.2424E-22"
        izz="0.00028999" />
    </inertial>
    <visual>
      <origin
        xyz="0 0 0"
        rpy="0 0 0" />
      <geometry>
        <mesh
          filename="package://srbot_description/meshes/left_wheel.STL" />
      </geometry>
      <material
        name="">
        <color
          rgba="0.79216 0.81961 0.93333 1" />
      </material>
    </visual>
    <collision>
      <origin
        xyz="0 0 0"
        rpy="0 0 0" />
      <geometry>
        <mesh
          filename="package://srbot_description/meshes/left_wheel.STL" />
      </geometry>
    </collision>
  </link>
  <joint
    name="left_joint"
    type="continuous">
    <origin
      xyz="0.1389 -0.24143 0.2866"
      rpy="1.5708 0 0" />
    <parent
      link="base_link" />
    <child
      link="left_wheel" />
    <axis
      xyz="0 0 0" />
  </joint>
  <link
    name="front_right_caster">
    <inertial>
      <origin
        xyz="0.0076552 -1.1102E-16 -0.027561"
        rpy="0 0 0" />
      <mass
        value="0.037642" />
      <inertia
        ixx="0.1"
        ixy="0.1"
        ixz="0.1"
        iyy="0.1"
        iyz="0.1"
        izz="0.1" />
    </inertial>
    <visual>
      <origin
        xyz="0 0 0"
        rpy="0 0 0" />
      <geometry>
        <mesh
          filename="package://srbot_description/meshes/front_right_caster.STL" />
      </geometry>
      <material
        name="">
        <color
          rgba="0.79216 0.81961 0.93333 1" />
      </material>
    </visual>
    <collision>
      <origin
        xyz="0 0 0"
        rpy="0 0 0" />
      <geometry>
        <mesh
          filename="package://srbot_description/meshes/front_right_caster.STL" />
      </geometry>
    </collision>
  </link>
  <joint
    name="front_left_joint"
    type="continuous">
    <origin
      xyz="0.2774 -0.52643 0.29318"
      rpy="0 0 0" />
    <parent
      link="base_link" />
    <child
      link="front_right_caster" />
    <axis
      xyz="0 0 0" />
  </joint>
  <link
    name="front_left_caster">
    <inertial>
      <origin
        xyz="0.0076552 0 -0.027561"
        rpy="0 0 0" />
      <mass
        value="0.037642" />
      <inertia
        ixx="0.1"
        ixy="0.1"
        ixz="0.1"
        iyy="0.1"
        iyz="0.1"
        izz="0.1" />
    </inertial>
    <visual>
      <origin
        xyz="0 0 0"
        rpy="0 0 0" />
      <geometry>
        <mesh
          filename="package://srbot_description/meshes/front_left_caster.STL" />
      </geometry>
      <material
        name="">
        <color
          rgba="0.79216 0.81961 0.93333 1" />
      </material>
    </visual>
    <collision>
      <origin
        xyz="0 0 0"
        rpy="0 0 0" />
      <geometry>
        <mesh
          filename="package://srbot_description/meshes/front_left_caster.STL" />
      </geometry>
    </collision>
  </link>
  <joint
    name="front_left_joint"
    type="continuous">
    <origin
      xyz="0.2774 -0.28643 0.29318"
      rpy="0 0 0" />
    <parent
      link="base_link" />
    <child
      link="front_left_caster" />
    <axis
      xyz="0 0 0" />
  </joint>
  <link
    name="back_right_caster">
    <inertial>
      <origin
        xyz="0.0076552 -1.1102E-16 -0.027561"
        rpy="0 0 0" />
      <mass
        value="0.037642" />
      <inertia
        ixx="0.1"
        ixy="0.1"
        ixz="0.1"
        iyy="0.1"
        iyz="0.1"
        izz="0.1" />
    </inertial>
    <visual>
      <origin
        xyz="0 0 0"
        rpy="0 0 0" />
      <geometry>
        <mesh
          filename="package://srbot_description/meshes/back_right_caster.STL" />
      </geometry>
      <material
        name="">
        <color
          rgba="0.79216 0.81961 0.93333 1" />
      </material>
    </visual>
    <collision>
      <origin
        xyz="0 0 0"
        rpy="0 0 0" />
      <geometry>
        <mesh
          filename="package://srbot_description/meshes/back_right_caster.STL" />
      </geometry>
    </collision>
  </link>
  <joint
    name="back_right_joint"
    type="continuous">
    <origin
      xyz="0.0054009 -0.52643 0.29318"
      rpy="0 0 0" />
    <parent
      link="base_link" />
    <child
      link="back_right_caster" />
    <axis
      xyz="0 0 0" />
  </joint>
  <link
    name="back_left_caster">
    <inertial>
      <origin
        xyz="0.0076552 0 0"
        rpy="0 0 0" />
      <mass
        value="0" />
      <inertia
        ixx="0.1"
        ixy="0.1"
        ixz="0.1"
        iyy="0.1"
        iyz="0.1"
        izz="0.1" />
    </inertial>
    <visual>
      <origin
        xyz="0 0 0"
        rpy="0 0 0" />
      <geometry>
        <mesh
          filename="package://srbot_description/meshes/back_left_caster.STL" />
      </geometry>
      <material
        name="">
        <color
          rgba="1 1 1 1" />
      </material>
    </visual>
    <collision>
      <origin
        xyz="0 0 0"
        rpy="0 0 0" />
      <geometry>
        <mesh
          filename="package://srbot_description/meshes/back_left_caster.STL" />
      </geometry>
    </collision>
  </link>
  <joint
    name="back_left_caster"
    type="continuous">
    <origin
      xyz="0.0054009 -0.28643 0.29318"
      rpy="0 0 0" />
    <parent
      link="base_link" />
    <child
      link="back_left_caster" />
    <axis
      xyz="0 0 0" />
  </joint>
</robot>